Workbook

Sheet Base
A1: nom | B1: t.zinc (mg/g) | C1: t.mg (mg/g) | D1: t.vitd (mg/g) | E1: t.vitc (mg/g) | F1: t.fer (mg/g) | G1: t.prot | H1: t.glu | I1: t.lip | J1: t.kcal | K1: type | L1: saison
A2: Poulet | B2: =0.72 -> 0.72 | C2: =37 -> 37 | D2: =0 -> 0 | E2: =1.43 -> 1.43 | F2: 0.39 | G2: 26 | H2: 0 | I2: 2 | J2: 140
A3: Steak | B3: =5.05 -> 5.05 | C3: =28.6 -> 28.6 | D3: =0 -> 0 | E3: =0 -> 0 | F3: =2.62 -> 2.62 | G3: 28 | H3: 0 | I3: 5 | J3: 157
A4: Thon | B4: =0.44 -> 0.44 | C4: =46 -> 46 | D4: =1.83 -> 1.83 | E4: =0 -> 0 | F4: =1.8 -> 1.8 | G4: 26 | H4: 0 | I4: 2 | J4: 177
A5: Œufs (1u) | B5: =1.1 -> 1.1 | C5: =10.8 -> 10.8 | D5: =2 -> 2 | E5: =0 -> 0 | F5: =1.75 -> 1.75 | G5: =0.6*11 -> 6.6 | H5: =0.6*2 -> 1.2 | I5: =0.6*10 -> 6 | J5: =0.6*148 -> 88.8
A6: Feta | G6: 14 | H6: 4 | I6: 21 | J6: 264
A7: Lentilles | B7: =1.1 -> 1.1 | C7: =31 -> 31 | D7: =0 -> 0 | E7: =0 -> 0 | F7: =2.5 -> 2.5 | G7: 8 | H7: 13 | I7: 0 | J7: 90
A8: Lardon | B8: =2.1 -> 2.1 | C8: =22 -> 22 | D8: =0 -> 0 | E8: =0 -> 0 | F8: =0.5 -> 0.5 | G8: 24 | H8: 2 | I8: 26 | J8: 338
A9: Jambon | G9: 18 | H9: 0 | I9: 6 | J9: 134
A10: Pois chiche | B10: =1.1 -> 1.1 | C10: =44 -> 44 | D10: =0 -> 0 | E10: =0 -> 0 | F10: =1.3 -> 1.3 | G10: =7 -> 7 | H10: =15 -> 15 | I10: =3 -> 3 | J10: =118 -> 118
A11: Tranche de poulet | B11: =0.72 -> 0.72 | C11: =37 -> 37 | D11: =0 -> 0 | E11: =1.43 -> 1.43 | F11: 0.39 | G11: =25 -> 25 | H11: =1 -> 1 | I11: =2 -> 2 | J11: =105 -> 105
A12: Cordon bleu | B12: =1.16 -> 1.16 | C12: =37.6 -> 37.6 | D12: =0 -> 0 | E12: =0 -> 0 | F12: =0.68 -> 0.68 | G12: =14 -> 14 | H12: =15 -> 15 | I12: =12 -> 12 | J12: =220 -> 220
A13: Croquette de colin | B13: =0.46 -> 0.46 | C13: =34.8 -> 34.8 | D13: =0.73 -> 0.73 | E13: =1.09 -> 1.09 | F13: =0.2 -> 0.2 | G13: =12 -> 12 | H13: =13 -> 13 | I13: =7 -> 7 | J13: =166 -> 166
A14: Filet de colin | B14: =0.46 -> 0.46 | C14: =34.8 -> 34.8 | D14: =0.73 -> 0.73 | E14: =1.09 -> 1.09 | F14: =0.2 -> 0.2 | G14: =16 -> 16 | H14: =0 -> 0 | I14: =1 -> 1 | J14: =73 -> 73
A15: Poisson | B15: =0.61 -> 0.61 | C15: =30 -> 30 | D15: =3.69 -> 3.69 | E15: =0.96 -> 0.96 | F15: =0.69 -> 0.69 | G15: =22 -> 22 | H15: =0 -> 0 | I15: =2 -> 2 | J15: =100 -> 100
A16: Banane (1u) | B16: =0.14 -> 0.14 | C16: =28 -> 28 | D16: =0 -> 0 | E16: =7.16 -> 7.16 | F16: =0.2 -> 0.2 | G16: =1.2*1.5 -> 1.8 | H16: =1.2*32 -> 38.4 | I16: =1.2*1 -> 1.2 | J16: =1.2*136 -> 163.2
A17: Clémentine (1u) | B17: =0.1 -> 0.1 | C17: =0 -> 0 | D17: =0 -> 0 | E17: =49.2 -> 49.2 | F17: =0.09 -> 0.09 | G17: =0.5*1 -> 0.5 | H17: =0.5*10 -> 5 | I17: 0 | J17: =0.5*45 -> 22.5
A18: Pomme | B18: =0 -> 0 | C18: =3 -> 3 | D18: =0 -> 0 | E18: =2.13 -> 2.13 | F18: =0.07 -> 0.07 | G18: 0 | H18: 17 | I18: 0 | J18: 73
A19: Fromage blanc | G19: 7 | H19: 8 | I19: 0 | J19: 62
A20: Amandier | G20: 5 | H20: 45 | I20: 24 | J20: 421
A21: Kinder délice | G21: 5 | H21: 45 | I21: 30 | J21: 474
A22: Petit écolier | G22: 7 | H22: 65 | I22: 24 | J22: 500
A23: Cookies Granola | G23: 6 | H23: 64 | I23: 23 | J23: 495
A24: Miel | G24: =0 -> 0 | H24: =85 -> 85 | I24: =0 -> 0 | J24: =330 -> 330
A25: Beurre de cacahuète | B25: =2.76 -> 2.76 | C25: =174 -> 174 | D25: =0 -> 0 | E25: =0 -> 0 | F25: =1.92 -> 1.92 | G25: =25 -> 25 | H25: =16 -> 16 | I25: =52 -> 52 | J25: =640 -> 640
A26: Yaourt perle de lait | B26: =0.38 -> 0.38 | C26: =11.5 -> 11.5 | D26: =0.48 -> 0.48 | E26: =0.28 -> 0.28 | F26: =0.16 -> 0.16 | G26: =3 -> 3 | H26: =13 -> 13 | I26: =7 -> 7 | J26: =130 -> 130
A27: Yaourt la laitière | B27: =0.38 -> 0.38 | C27: =11.5 -> 11.5 | D27: =0.48 -> 0.48 | E27: =0.28 -> 0.28 | F27: =0.16 -> 0.16 | G27: =3 -> 3 | H27: =13 -> 13 | I27: =3 -> 3 | J27: =91 -> 91
A28: Pain de mie (u) | B28: =0.49 -> 0.49 | C28: =20 -> 20 | E28: =0 -> 0 | F28: =0.74 -> 0.74 | G28: =7/4 -> 1.75 | H28: =48/4 -> 12 | I28: =3/4 -> 0.75 | J28: =250/4 -> 62.5
A29: Compote Andros | G29: 0 | H29: 16 | I29: 0 | J29: 70
A30: Pâtes completes | B30: =0.99 -> 0.99 | C30: =36 -> 36 | D30: =0 -> 0 | E30: =0 -> 0 | F30: =0.98 -> 0.98 | G30: 12 | H30: 67 | I30: 2 | J30: 345
A31: Riz basmati (cru) | B31: =0.62 -> 0.62 | C31: =49 -> 49 | D31: =0 -> 0 | E31: =0 -> 0 | F31: =0.32 -> 0.32 | G31: 8 | H31: 78 | I31: 0 | J31: 348
A32: Pomme de terre | B32: =0.24 -> 0.24 | C32: =21.7 -> 21.7 | D32: =0 -> 0 | E32: =12.8 -> 12.8 | F32: =0.35 -> 0.35 | G32: 2 | H32: 18 | I32: 0 | J32: 85
A33: Pain complet | G33: 9 | H33: 51 | I33: 2 | J33: 269
A34: Boulgour | G34: 12 | H34: 76 | I34: 1 | J34: 342
A35: Quinoa | G35: 5 | H35: 29 | I35: 3 | J35: 160
A36: Haricot vert | G36: 2 | H36: 4 | I36: 0 | J36: 24
A37: Sauce tomate | G37: 1 | H37: 6 | I37: 3 | J37: 60
A38: Crème frâche | G38: 3 | H38: 4 | I38: 30 | J38: 300
A39: Lait de coco | G39: 2 | H39: 3 | I39: 21 | J39: 210
A40: Ratatouille | G40: 2 | H40: 8 | I40: 4 | J40: 76
...

Sheet Besoin
A1: Modèle | B1: Formule | C1: Densité.e glucide (kcal/g) | D1: Densité.e lipide (kcal/g) | E1: Densité.e protéine (kcal/g) | F1: Masse totale (kg) | G1: Masse grasse (kg) | H1: Masse maigre (kg) | I1: BMR (kcal) | J1: Facteur activité | K1: TDEE (kcal) | L1: Modèle répartition des macros | M1: Masse protéine (g) | N1: Masse glucides (g) | O1: Masse lipides (g) | P1: kcal protéine | Q1: kcal lipides | R1: kcal glucides
A2: Katch-McArdle | B2: BMR=370+(21,6×massemaigreenkg) | C2: 4 | D2: 9 | E2: 4 | F2: =73 -> 73 | G2: =4.5 -> 4.5 | H2: =F2-G2 -> 68.5 | I2: =370+(21.6*H2) -> 1849.6 | J2: =1.55 -> 1.55 | K2: =I2*J2 -> 2866.88 | L2: 2 g/kg de protéine (20%) 50% glucides 30% lipides | M2: =2*F2 -> 146 | N2: =R2/C2 -> 358.36 | O2: =Q2/D2 -> 95.562667 | P2: =M2*E2 -> 584 | Q2: =0.3*K2 -> 860.064 | R2: =0.5*K2 -> 1433.44

Sheet Menu
A1: Nom | B1: m.prot | C1: m.glu | D1: m.lip | E1: kcal | F1: diff.prot | G1: diff.glu | H1: diff.lip | I1: diff.kcal
A2: M1 | B2: 129.56 | C2: 350.88 | D2: 54.94 | E2: 2513.29 | F2: =Besoin!$M$2-B2 -> 16.44 | G2: =Besoin!$N$2-C2 -> 7.48 | H2: =Besoin!$O$2-Menu!D2 -> 40.622667 | I2: =Besoin!$K$2-Menu!E2 -> 353.59
A3: M2 | B3: 124.66 | C3: 375.56 | D3: 70.63 | E3: 2503.29 | F3: =Besoin!$M$2-B3 -> 21.34 | G3: =Besoin!$N$2-C3 -> -17.2 | H3: =Besoin!$O$2-Menu!D3 -> 24.932667 | I3: =Besoin!$K$2-Menu!E3 -> 363.59
A4: M3 | B4: 113.06 | C4: 354.78 | D4: 77.74 | E4: 2622.04 | F4: =Besoin!$M$2-B4 -> 32.94 | G4: =Besoin!$N$2-C4 -> 3.58 | H4: =Besoin!$O$2-Menu!D4 -> 17.822667 | I4: =Besoin!$K$2-Menu!E4 -> 244.84
A5: M4 | B5: 124.56 | C5: 301.58 | D5: 73.54 | E5: 2511.84 | F5: =Besoin!$M$2-B5 -> 21.44 | G5: =Besoin!$N$2-C5 -> 56.78 | H5: =Besoin!$O$2-Menu!D5 -> 22.022667 | I5: =Besoin!$K$2-Menu!E5 -> 355.04
A6: M5 | B6: 126.64 | C6: 307.13 | D6: 75.94 | E6: 2505.09 | F6: =Besoin!$M$2-B6 -> 19.36 | G6: =Besoin!$N$2-C6 -> 51.23 | H6: =Besoin!$O$2-Menu!D6 -> 19.622667 | I6: =Besoin!$K$2-Menu!E6 -> 361.79
A7: M6 | B7: 128.36 | C7: 293.98 | D7: 78.74 | E7: 2475.49 | F7: =Besoin!$M$2-B7 -> 17.64 | G7: =Besoin!$N$2-C7 -> 64.38 | H7: =Besoin!$O$2-Menu!D7 -> 16.822667 | I7: =Besoin!$K$2-Menu!E7 -> 391.39
A8: M7 | B8: 131.3 | C8: 304.03 | D8: 76.39 | E8: 2554.54 | F8: =Besoin!$M$2-B8 -> 14.7 | G8: =Besoin!$N$2-C8 -> 54.33 | H8: =Besoin!$O$2-Menu!D8 -> 19.172667 | I8: =Besoin!$K$2-Menu!E8 -> 312.34
F9: =AVERAGE(F2:F8) -> 20.551429 | G9: =AVERAGE(G2:G8) -> 31.511429 | H9: =AVERAGE(H2:H8) -> 23.002667 | I9: =AVERAGE(I2:I8) -> 340.36857
F10: 13.5 | G10: 44.25 | H10: 23.25 | I10: 447.5

Sheet Feuil3
A1: Yaourt perle de lait | B1: =3 -> 3 | C1: =13 -> 13 | D1: =7 -> 7 | E1: =130 -> 130
A2: Pain de mie (u) | B2: =7/4 -> 1.75 | C2: =48/4 -> 12 | D2: =3/4 -> 0.75 | E2: =250/4 -> 62.5
A3: Beurre de cacahuète | B3: =25 -> 25 | C3: =16 -> 16 | D3: =52 -> 52 | E3: =640 -> 640
A5: 1 yaourt | B5: =1.25*B1 -> 3.75 | C5: =1.25*C1 -> 16.25 | D5: =1.25*D1 -> 8.75 | E5: =1.25*E1 -> 162.5
A6: 2 pain de mie | B6: =2*B2 -> 3.5 | C6: =2*C2 -> 24 | D6: =2*D2 -> 1.5 | E6: =2*E2 -> 125
A7: 25g beurre | B7: =0.25*B3 -> 6.25 | C7: =0.25*C3 -> 4 | D7: =0.25*D3 -> 13 | E7: =0.25*E3 -> 160
A8: Total | B8: =SUM(B5:B7) -> 13.5 | C8: =SUM(C5:C7) -> 44.25 | D8: =SUM(D5:D7) -> 23.25 | E8: =SUM(E5:E7) -> 447.5
